## 9.1 프로그램 오류, 예외 클래스의 계층 구조

> **1. 에러** : 컴퓨터 하드웨어 오작동, 고장으로 응용프로그램 실행 오류 발생(ex. 화재 장애)
2. **예외** : 프로그램 코드에 의해 수습될 수 있는 오류
> 

예외처리 : 프로그램 실행 시 발생할 수 있는 예외 발생에 대비한 코드 작성 목적

### 프로그램 오류

1. 컴파일 에러
2. 런타임 에러
3. 논리적 오류

<br>

## 예외 발생 예시

### 예시 1. 어떤 객체의 메서드를 호출했는데 해당 객체가 null인
경우

```java
String str = null;
int length = str.length(); // NullPointerException 발생
```

### 예시 2. 배열의 범위를 벗어나는 인덱스에 접근한 경우

```java
int[] arr = {1, 2, 3};
int value = arr[3]; // ArrayIndexOutOfBoundsException 발생
```

### 예시 3. 존재하지 않는 파일을 열려고 시도한 경우

```java
FileReader fileReader = new FileReader("test.txt"); 
// FileNotFoundException 발생
```

### 예시 4. 데이터베이스와 관련된 문제가 발생한 경우

```java
ResultSet resultSet = statement.executeQuery("SELECT * FROM tb_test"); 
// 잘못된 SQL일 경우 SQLException 발생
```

## 예외 처리를 해야하는 이유

### 1. 안정성 확보

예외가 발생하더라도 프로그램이 갑작스럽게 종료되거나 오작동을 하지 않게 적절히
대응할 수 있습니다. 예를 들어 은행 시스템에서 송금을 하는 도중 예외가 발생했다고
가정해봅시다. 송금에 실패했다고 시스템을 종료하는 것이 아니라 송금하기 이전의 상태로
되돌리는(rollback) 등의 처리를 할 수 있을 것입니다.

### 2. 유지보수 용이

예외가 발생했을 때 로그를 남길 수 있습니다. 로그란 어떤 이벤트에 대한 기록을
의미합니다. 로그를 자세히 남겨놓을 수록 예외가 발생한 곳의 위치를 파악하기 쉽고,
디버깅을 용이하게 해줍니다.

### 3. 사용자 경험 향상

예외가 발생했을 때 프로그램을 종료하는 것이 아니라 사용자에게 안내 문구를 보여준다면 사용자가 문제를 이해하는 데 도움을 줄 수 있을 것입니다.

### 4. 자원 관리

예외 처리를 통해 자원을 안전하게 관리할 수 있습니다. 예를 들어 파일을 다루는
프로그램의 경우 파일을 열고 작업을 수행 중에 예외가 발생할 수 있습니다. 이럴 경우
데이터가 완전히 파일에 기록되지 않을 수도 있습니다. 예외 처리를 통해 파일을 닫는다면
데이터의 기록을 보장할 수 있습니다.

<br><br>

## 9.1.2 예외 클래스의 계층 구조

예외 클래스 두 가지 종류

1. 일반 예외(Exception)
2. 실행 예외(Runtime Exception)

일반 예외 - 컴파일러 체크 예외(Checked Exception) : 컴파일 과정에서 예외처리 필요 유무 검사 → 예외 처리 코드 없을 경우 컴파일 오류

실행 예외 - 컴파일러가 체크하지 않는 예외(Unchecked Exception) : 컴파일 과정에서 예외 처리 코드를 검사하지 않음

<img src="https://github.com/csbcr19/TIL/assets/155497511/babc2cbc-dffe-45e2-a95c-61a805dca16a" width=600px>

<br><br>

## 9.2 예외처리

예외 처리는 예기치 않은 상황 또는 오류가 발생할 것을 예측하고 이에 대비하는 것이다.
프로그램의 신뢰성을 높일 수 있기 때문에 매우 중요한 작업이라고 할 수 있다.

### 자바에서 예외처리 방법

1. 발생가능성이 있는 곳에서 바로 처리(try-catch)
2. 나를 호출한 너가 대신 처리해줘(throws)

<br><br>

## 9.2.1 try-catch문

### try-catch문 기본 구조

```java
try {
// 예외가 발생할 수 있는 코드
} catch (Exception e) { 
// 예외 처리
}
```

```java
try {
    <수행할 문장 1>;
    <수행할 문장 2>;
    ...
} catch(예외1) {
    <수행할 문장 A>;
    ...
} catch(예외2) {
    <수행할 문장 a>;
    ...
}
```

```java
try {
    <수행할 문장 1>;
    <수행할 문장 2>;
    ...
} catch (예외1 | 예외2) {  
// 둘 중 하나가 예외일 경우 A 수행 
//(멀티 catch)
    <수행할 문장 A>;
    ...
}
```

첫 번째 코드의 try문 에서 예외가 발생하여 catch 예외1이 수행된다면 그 다음 예외2의 catch문은 수행되지 않습니다. 

그리고 try문 안의 수행할 문장 중 예외가 발생하지 않는다면 catch문 안의 내용은 수행되지 않습니다. 하지만 try문 수행 중 예외가 발생하면 catch문이 수행됩니다.

### 다중 catch문 작성시 주의사항

- 상위 예외클래스가 하위 예외 클래스보다 아래쪽에 위치해야한다

```java
try {
	(ArrayIndexOutOfBoundsException 발생)

	(NumberFormatException 발생)
} catch(Exception e) {
	예외처리1
} catch(ArrayIndexOutOfBoundsException e) {
	예외처리2    // 컴파일 오류
}
```

ArrayIndexOutOfBoundsException 예외와 NumberFormatException 예외는 모두 Exception을 상속받기 때문에 첫번째 catch 블록만 선택되어 실행된다.
두번째 catch블록은 어떤 경우에라도 실행되지 않는다.

```java
try {
	(ArrayIndexOutOfBoundsException 발생)

	(NumberFormatException 발생)
} catch(ArrayIndexOutOfBoundsException e) {
	예외처리1
} catch(Exception e) {
	예외처리2 
}
```

try 블록에서 ArrayIndexOutOfBoundsException이 발생하면 첫번째 catch 블록을 실행하고, 그 밖의 다른 예외가 발생하면 두 번째 catch 블록을 실행한다.

<br><br>

## 9.2.2 finally

프로그램 수행 도중 에러가 발생하면 프로그램이 중단되거나 예외 처리에 의해 catch 구문이 실행하지만 어떤 예외가 발생하더라도 반드시 실행되는 부분 ⇒ **finally** 구문

<img src="https://github.com/csbcr19/TIL/assets/155497511/398adc4f-6e59-4e48-8c8b-cfa00ef340e9" width=600px>

```java
public class DivideExceptionSample {
    void finalMessage() {
        System.out.println("그럼 수고하세요.");
    }

    public static void main(String[] args) {
        DivideExceptionSample sample = new DivideExceptionSample();
        int result;
        try {
            result = 5 / 0;
            sample.finalMessage();       // 이 코드는 실행되지 않는다.
        } catch (ArithmeticException e) {
            result = -1;
            System.out.println("숫자는 0으로 나눌 수 없습니다.");
        } finally {
            sample.finalMessage();    // 이곳에서는 예외와 상관없이 무조건 수행된다.
        }
    }
}
```

try문에서 **`sample.finalMessage();`** 는 절대로 실행될 수 없다. 
`result = 5 / 0;`가 실행되면서 ArithmeticException이 발생하여 catch 구문으로 예외처리가 넘어가기 때문이다. 
`result = 5 / 0;` 이후에 **`sample.finalMessage();`** 메소드가 반드시 실행되어야 한다면  finally문을 사용한다. 

```java
숫자는 0으로 나눌 수 없습니다.
그럼 수고하세요.
```
<br><br>

# 9.3 사용자 정의 예외와 예외발생

사용자 정의 예외 - 만족할 수 있는 예외가 없을 경우, 어떤 작업을 강제화하고 싶을 때
<br><br>

## 9.3.1 사용자 정의 예외 클래스 선언

```java
public class XXXException extends **Exception** { 
	public XXXException() { }
	public XXXException(String message) {  super(message);  }
}

or 

public class XXXException extends **RuntimeException** {
	public XXXException() { }
	public XXXException(String message) {  super(message);  }
}
```

### 사용자 정의 예외 클래스

1. 컴파일러가 체크하는(CheckedException) **일반 예외**로 선언할 수도 있다.
2. 컴파일러가 체크하지 않는(UnCheckedException) **실행 예외**로 선언할 수도 있다. 

일반 예외로 선언할 경우 Exception 상속, 실행 예외로 선언할 경우 RuntimeException 상속.

- 사용자 정의 예외 클래스의 네이밍도 `Exception`으로 끝내기
- 사용자 정의 예외 클래스도 필드, 생성자, 메소드 선언들을 포함할 수 있지만 대부분 생성자 선언만을 포함 생성자는 두 개를 선언하는 것이 일반적인데,

1. 하나는 매개변수가 없는 기본 생성자 이고, 
    
    ```java
    public XXXException() { }
    ```
    

1. 다른 하나는 예외 발생 원인 메시지를 전달을 위해 String 타입의 매개 변수를 갖는 생성자 이다.
    
    ```java
    public XXXException(String message) {  super(message);  }
    ```
    
    String 타입의 매개 변수를 갖는 생성자는 상위 클래스의 생성자를 호출하여 예외 메시지를 넘겨줌. 예외 메시지의 용도는 catch { } 블록의 예외 처리 코드에서 이용하기 위함. 
    
    ```java
    public class BalanceInsufficientException extends Exception {
    	public BalanceInsufficientException() {
    	}
    
    	public BalanceInsufficientException(String message) { //에러메세지
    		super(message);
    	}
    }
    ```
    
    `BalanceInsufficientException` 은 `Exception`을 상속하기 때문에 컴파일러에 의해 체크되는 예외가 됩니다. 그래서 소스 작성시 **try-catch 블록으로 예외 처리가 필요**합니다. 
    

### throw와 throws의 차이

**차이점**

- throw: **메소드 내**에서 **예외를 최초로 발생**시키는 데 사용됨 (`throw new BalanceInsufficientException()`)
    - 굳이 직접 예외를 발생 시키는가? → 로직 방어 목정
- throws: 메소드 **선언부**에서 사용되며, 해당 메소드가 처리하지 않은 예외를 **호출자에게 전달**한다는 의미를 내포하고 있음 (`public void withdraw(int money) throws BalanceInsufficientException`)

> throw : 예외를 던짐 (예외 발생)
throws : 예외를 떠넘김 (자신을 호출한 곳으로)
>